Workbook

Sheet in
A1: scopus_id | B1: doi | C1: title | D1: journal | E1: publication_year | F1: keywords | G1: abstract | H1: corresponding_author_country | I1: cited_by_count | J1: policy_claim_via_terms | K1: v1_llm_policy_claim | L1: DB review | M1: DB notes | N1: EC review | O1: EC notes | P1: DB notes | Q1: v1.9_updated LLM prompt claim | T1: MW review | U1: MW notes | W1: llm_policy_claim
A2: SCOPUS_ID:78650633722 | B2: 10.1093/aje/kwq345 | C2: Adult body size, hormone receptor status, and premenopausal breast cancer risk in a multiethnic population | D2: American Journal of Epidemiology | E2: 2011 | F2: ['African Americans', 'body size', 'breast neoplasms', 'Hispanic Americans', 'premenopause', 'receptors, estrogen', 'receptors, progesterone'] | G2: Large body size has been associated with a reduced risk of premenopausal breast cancer in non-Hispanic white women. Data on other racial/ethnic populations are limited. The authors examined the association between premenopausal breast cancer risk and adult body size in 672 cases and 808 controls aged â‰¥35 years from a population-based case-control study conducted in 1995-2004 in the San Francisco Bay Area (Hispanics: 375 cases, 483 controls; African Americans: 154 cases, 160 controls; non-Hispanic whites: 143 cases, 165 controls). Multivariate adjusted odds ratios and 95% confidence intervals were calculated using unconditional logistic regression. Height was associated with increased breast cancer risk (highest vs. lowest quartile: odds ratio = 1.77, 95% confidence interval: 1.23, 2.53; Ptrend < 0.01); the association did not vary by hormone receptor status or race/ethnicity. Body mass index (measured as weight (kg) divided by height (m) squared) was inversely associated with risk in all 3 racial/ethnic groups, but only for estrogen receptor- and progesterone receptor-positive tumors (body mass index â‰¥30 vs. <25: odds ratio = 0.42; 95% confidence interval: 0.29, 0.61). Other body size measures (current weight, body build, adult weight gain, young adult weight and body mass index, waist circumference, and waist-to-height ratio) were similarly inversely associated with risk of estrogen receptor- and progesterone receptor-positive breast cancer but not estrogen receptor- and progesterone receptor-negative disease. Despite racial/ethnic differences in body size, inverse associations were similar across the 3 racial/ethnic groups when stratified by hormone receptor status. Â© 2010 The Author. | H2: United States | I2: 59 | J2: FALSE | K2: FALSE | L2: FALSE | N2: FALSE | Q2: FALSE | R2: =IF(Q2<>N2,"!!!","") | W2: FALSE
A3: SCOPUS_ID:0032978484 | B3: 10.2105/AJPH.89.2.171 | C3: The impact of physician bonuses, enhanced fees, and feedback on childhood immunization coverage rates | D3: American Journal of Public Health | E3: 1999 | F3: [] | G3: Objectives. The purpose of this study was to examine the effects on immunization coverage of 3 incentives for physicians - a cash bonus for practice-wide increases, enhanced fee for service, and feedback. Methods. Incentives were applied at 4-month intervals over 1 year among 60 inner-city office-based pediatricians. At each interval, charts of 50 randomly selected children between 3 and 35 months of age were reviewed per physician. Results. The percentage of children who were up to date for diphtheria, tetanus, and pertussis and Haemophilus influenzae type b; polio; and measles-mumps- rubella immunization in the study's bonus group improved by 25.3 percentage points (P < .01). No significant changes occurred in the other groups. However, percentage of immunizations received outside the participating practice also increased significantly in the bonus group (P < .0.1). Levels of missed opportunities to immunize were high in all groups and did hot change over time. Physicians' knowledge of contraindications was low. Conclusions: Bonuses sharply and rapidly increased immunization coverage in medical records. However, much of the increase was the result of better documentation. A bonus is a powerful incentive, but more structure or education may be necessary to achieve the desired results. | H3: United States | I3: 139 | J3: FALSE | K3: TRUE | L3: FALSE | M3: marginal | N3: FALSE | O3: The final statement is strong but not really a policy recommendation - hard one. | P3: agree - may be intrinsic limit of LLMs | Q3: FALSE | R3: =IF(Q3<>N3,"!!!","") | W3: FALSE
A4: SCOPUS_ID:0032931075 | B4: 10.1093/oxfordjournals.aje.a009723 | C4: Prospective study of diet and ovarian cancer | D4: American Journal of Epidemiology | E4: 1999 | F4: ['Diet', 'Nutrition', 'Ovarian neoplasms', 'Postmenopausal', 'Prospective studies', 'Risk', 'Risk factors'] | G4: Evidence on dietary risk factors for ovarian cancer is inconsistent, but some studies have suggested positive associations with dietary fat, lactose, and cholesterol and negative associations with green and yellow vegetable intake. By using information from the Iowa Women's Health Study, the authors investigated the association of epithelial ovarian cancer with dietary factors in a prospective study of 29,083 postmenopausal women. Dietary information was ascertained via a food frequency questionnaire mailed to participants in 1986. During 10 years of follow-up (1986-1995), 139 of the women developed incident epithelial ovarian cancer. Incidence of the disease was not associated with dietary fat intake. Lactose and cholesterol showed moderately elevated risks. Multivariable-adjusted relative risks for the lowest to highest quartiles of lactose intake were 1.00, 1.38, 1.25, and 1.60 (p for trend = 0.12). For cholesterol, the corresponding values were 1.00, 1.34, 1.86, and 1.55 (p for trend = 0.06). Consumption of eggs was also associated with an increased risk of ovarian cancer. Multivariable-adjusted relative risks for increasing frequency of egg consumption were 1.00 (<1/week), 1.12 (1/week), 2.04 (2-4/week), and 1.81 (>4/week) (p for trend = 0.04). Total vegetable intake was modestly and inversely associated with the risk of ovarian cancer (p for trend = 0.21). Green leafy vegetable intake was more strongly associated with a decreased risk: multivariable-adjusted relative risks for the lowest to highest intake levels were 1.00, 0.80, 0.87, and 0.44 (p = 0.01). These findings are generally in agreement with the results from previous, mostly case-control studies of diet and epithelial ovarian cancer. | H4: United States | I4: 201 | J4: FALSE | K4: FALSE | L4: FALSE | N4: FALSE | Q4: FALSE | R4: =IF(Q4<>N4,"!!!","") | W4: FALSE
A5: SCOPUS_ID:85066260594 | B5: 10.1016/S2468-2667(19)30018-0 | C5: Geospatial, racial, and educational variation in firearm mortality in the USA, Mexico, Brazil, and Colombia, 1990â€“2015: a comparative analysis of vital statistics data | D5: The Lancet Public Health | E5: 2019 | F5: [] | G5: Background: Firearm mortality is a leading, and largely avoidable, cause of death in the USA, Mexico, Brazil, and Colombia. We aimed to assess the changes over time and demographic determinants of firearm deaths in these four countries between 1990 and 2015. Methods: In this comparative analysis of firearm mortality, we examined national vital statistics data from 1990â€“2015 from four publicly available data repositories in the USA, Mexico, Brazil, and Colombia. We extracted medically-certified deaths and underlying population denominators to calculate the age-specific and sex-specific firearm deaths and the risk of firearm mortality at the national and subnational level, by education for all four countries, and by race or ethnicity for the USA and Brazil. Analyses were stratified by intent (homicide, suicide, unintentional, or undetermined). We quantified avoidable mortality for each country using the lowest number of subnational age-specific and period-specific death rates. Findings: Between 1990 and 2015, 106Â·3 million medically-certified deaths were recorded, including 2 472 000 firearm deaths, of which 851 000 occurred in the USA, 272 000 in Mexico, 855 000 in Brazil, and 494 000 in Colombia. Homicides accounted for most of the firearm deaths in Mexico (225 000 [82Â·7%]), Colombia (463 000 [93Â·8%]), and Brazil (766 000 [89Â·5%]). Suicide accounted for more than half of all firearm deaths in the USA (479 000 [56Â·3%]). In each country, firearm mortality was highest among men aged 15â€“34 years, accounting for up to half of the total risk of death in that age group. During the study period, firearm mortality risks increased in Mexico and Brazil but decreased in the USA and Colombia, with marked national and subnational geographical variation. Young men with low educational attainment were at increased risk of firearm homicide in all four countries, and in the USA and Brazil, black and brown men, respectively, were at the highest risk. The risk of firearm homicide was 14 times higher in black men in the USA aged 25â€“34 years with low educational attainment than comparably-educated white men (1Â·52% [99% CI 1Â·50â€“1Â·54] vs 0Â·11% [0Â·10â€“0Â·12]), and up to four times higher than in comparably-educated men in Brazil, Colombia, and Mexico. In the USA, the risk of firearm homicide was more than 30 times higher in black men with post-secondary education than comparably educated white men. If countries could achieve the same firearm mortality rates nationally as in their lowest-burden states, 1 777 800 firearm deaths at all ages and in both sexes could be avoided, including 1 028 000 deaths in men aged 15â€“34 years. Interpretation: Firearm mortality in the USA, Mexico, Brazil, and Colombia is highest among young adult men, and is strongly associated with race and ethnicity, and low education levels. Reductions in firearm deaths would improve life expectancy, particularly for black men in the USA, and would reduce racial and educational disparities in mortality. Funding: Canadian Institutes of Health Research and the University of Toronto Connaught Global Challenge. | H5: Mexico | I5: 26 | J5: FALSE | K5: TRUE | L5: FALSE | M5: marginal | N5: FALSE | O5: I think it is worded carefully ('could'). Is the use of conditional something we could add to our algorithm? | P5: I don't think so for the terms approach. For the analysis in which study design is correlated with claims, we can manually screen the "made policy claim" group. | Q5: FALSE | R5: =IF(Q5<>N5,"!!!","") | W5: TRUE
A6: SCOPUS_ID:84895890934 | B6: 10.1093/aje/kwt327 | C6: Trends in alcohol and other drugs detected in fatally injured drivers in the United States, 1999-2010 | D6: American Journal of Epidemiology | E6: 2014 | F6: ['accidents', 'alcohol consumption', 'cannabinoids', 'drug users', 'motor vehicles', 'prescription drugs', 'safety', 'traffic'] | G6: Drugged driving is a safety issue of increasing public concern. Using data from the Fatality Analysis Reporting System for 1999-2010, we assessed trends in alcohol and other drugs detected in drivers who were killed within 1 hour of a motor vehicle crash in 6 US states (California, Hawaii, Illinois, New Hampshire, Rhode Island, and West Virginia) that routinely performed toxicological testing on drivers involved in such crashes. Of the 23,591 drivers studied, 39.7% tested positive for alcohol and 24.8% for other drugs. During the study period, the prevalence of positive results for nonalcohol drugs rose from 16.6% in 1999 to 28.3% in 2010 (Z =-10.19, P < 0.0001), whereas the prevalence of positive results for alcohol remained stable. The most commonly detected nonalcohol drug was cannabinol, the prevalence of which increased from 4.2% in 1999 to 12.2% in 2010 (Z =-13.63, P < 0.0001). The increase in the prevalence of nonalcohol drugs was observed in all age groups and both sexes. These results indicate that nonalcohol drugs, particularly marijuana, are increasingly detected in fatally injured drivers. Â© 2014 The Author. | H6: United States | I6: 168 | J6: FALSE | K6: FALSE | L6: FALSE | N6: FALSE | Q6: FALSE | R6: =IF(Q6<>N6,"!!!","") | W6: FALSE
A7: SCOPUS_ID:84912129265 | B7: 10.1016/j.amepre.2014.08.009 | C7: Adult vaccination disparities among foreign-born populations in the u.s., 2012 | D7: American Journal of Preventive Medicine | E7: 2014 | F7: [] | G7: Background Foreign-born persons are considered at higher risk of undervaccination and exposure to many vaccine-preventable diseases. Information on vaccination coverage among foreign-born populations is limited. | H7: United States | I7: 65 | J7: FALSE | K7: FALSE | L7: FALSE | M7: n/a abstract | N7: FALSE | O7: I dont know how frequent that is, but we might want to remove these? | P7: edited scripts to exclude abstracts <100 words | Q7: FALSE | R7: =IF(Q7<>N7,"!!!","") | W7: FALSE
A8: SCOPUS_ID:69549088896 | B8: 10.1097/EDE.0b013e3181ad5522 | C8: Extreme high temperatures and hospital admissions for respiratory and cardiovascular diseases | D8: Epidemiology | E8: 2009 | F8: [] | G8: BACKGROUND: Although the association of high temperatures with mortality is well-documented, the association with morbidity has seldom been examined. We assessed the potential impact of hot weather on hospital admissions due to cardiovascular and respiratory diseases in New York City. We also explored whether the weather-disease relationship varies with socio-demographic variables. METHOD: We investigated effects of temperature and humidity on health by linking the daily cardiovascular and respiratory hospitalization counts with meteorologic conditions during summer, 1991-2004. We used daily mean temperature, mean apparent temperature, and 3-day moving average of apparent temperature as the exposure indicators. Threshold effects for health risks of meteorologic conditions were assessed by log-linear threshold models, after controlling for ozone, day of week, holidays, and long-term trend. Stratified analyses were used to evaluate temperature-demographic interactions. RESULTS: For all 3 exposure indicators, each degree C above the threshold of the temperature-health effect curve (29Â°C-36Â°C) was associated with a 2.7%-3.1% increase in same-day hospitalizations due to respiratory diseases, and an increase of 1.4%-3.6% in lagged hospitalizations due to cardiovascular diseases. These increases for respiratory admissions were greater for Hispanic persons (6.1%/Â°C) and the elderly (4.7%/Â°C). At high temperatures, admission rates increased for chronic airway obstruction, asthma, ischemic heart disease, and cardiac dysrhythmias, but decreased for hypertension and heart failure. CONCLUSIONS: Extreme high temperature appears to increase hospital admissions for cardiovascular and respiratory disorders in New York City. Elderly and Hispanic residents may be particularly vulnerable to the temperature effects on respiratory illnesses. Â© 2009 Lippincott Williams & Wilkins, Inc. | H8: United States | I8: 366 | J8: FALSE | K8: FALSE | L8: FALSE | N8: FALSE | Q8: FALSE | R8: =IF(Q8<>N8,"!!!","") | W8: FALSE
A9: SCOPUS_ID:85088828588 | B9: 10.1007/s10654-020-00665-w | C9: Body mass index in young adulthood and risk of subsequent dementia at different levels of intelligence and education in Danish men | D9: European Journal of Epidemiology | E9: 2020 | F9: ['Body mass index', 'Cohort study', 'Dementia', 'Intelligence'] | G9: The risk of dementia seems to be established already early in life, which leads to the question if overweight early in life is an important risk factor for dementia as it appears to be later in life. We examined the association between body mass index (BMI) at entry to adult life and subsequent risk of dementia in men and assessed whether the relationship differed by levels of intelligence and education. The study population consisted of 377,598 Danish men born 1939â€“1959 with measures of height, weight, intelligence test score (ITS), and educational level (EL) at conscript board examinations around the age of 19Â years. Dementia outcomes were obtained from National Patient and Prescription Registries between 1969 and 2016. The association between BMI and dementia was analysed using Cox proportional hazard regression including interactions between BMI and ITS and EL, respectively. During the follow-up through age 77 years, 6144 (1.6%) developed dementia. The frequency was highest in men with lowest BMI, lowest ITS and lowest EL. Young adult BMI below the mean of 21.8Â kg/m2 was inversely associated with subsequent dementia, whereas there was no association with higher levels of BMI. Adjustment for young adult ITS and EL attenuated the risk estimates slightly, and interaction analyses showed that the shape of the association between BMI and dementia was unaffected by the levels of ITS and EL. Regardless of levels of ITS and EL, young adult BMI below the mean is inversely associated with subsequent dementia, whereas there is no association with higher levels of BMI. | H9: Denmark | I9: 5 | J9: FALSE | K9: FALSE | L9: FALSE | N9: FALSE | Q9: FALSE | R9: =IF(Q9<>N9,"!!!","") | W9: FALSE
A10: SCOPUS_ID:85054204629 | B10: 10.1093/aje/kwy091 | C10: Ramadan Exposure in Utero and Child Mortality in Burkina Faso: Analysis of a Population-Based Cohort Including 41,025 Children | D10: American Journal of Epidemiology | E10: 2018 | F10: ['child mortality', 'difference in differences', 'population-based cohort', 'pregnancy', 'prenatal exposure delayed effects', 'Ramadan', 'sub-Saharan Africa'] | G10: Ramadan exposure in utero can be regarded as a natural experiment with which to study how nutritional conditions in utero influence susceptibility to disease later in life. We analyzed data from rural Burkina Faso on 41,025 children born between 1993 and 2012, of whom 25,093 were born to Muslim mothers. Ramadan exposure was assigned on the basis of overlap between Ramadan dates and gestation, creating 7 exclusive categories. We used proportional hazards regression with difference-in-differences analysis to estimate the association between Ramadan exposure at different gestational ages and mortality among children under 5 years of age. Under-5 mortality was 32 deaths per 1,000 child-years. Under-5 mortality among Muslims was 15% higher than that among non-Muslims (P < 0.001). In the difference-in-differences analysis, the occurrence of Ramadan during conception or the first or second trimester was associated with higher under-5 mortality rates among Muslims only. The mortality rates of children born to Muslim mothers were 33%, 29%, and 22% higher when Ramadan occurred during conception, the first trimester, and the second trimester, respectively, compared with children of non-Muslim mothers born at the same time (P = 0.01, P < 0.001, and P = 0.007). Having a Muslim mother was not associated with mortality when the child was not exposed to Ramadan, born during Ramadan, or exposed during the third trimester. Observance of Ramadan during early pregnancy can have detrimental consequences for the future health of the unborn child. | H10: Germany | I10: 24 | J10: FALSE | K10: FALSE | L10: FALSE | M10: overly bold conclusion, but not a policy claims | N10: FALSE | O10: Agreed, maybe the tense is important here - can vs could. | P10: good, in which case all agree | Q10: FALSE | R10: =IF(Q10<>N10,"!!!","") | W10: FALSE
A11: SCOPUS_ID:84946734426 | B11: 10.2105/AJPH.2015.302611 | C11: Health care disparities in the post-affordable care act era | D11: American Journal of Public Health | E11: 2015 | F11: [] | G11: Disparities in health care have been targeted for elimination by federal agencies and professional organizations, including the American Public Health Association. Although the Affordable Care Act (ACA) provides a valuable first step in reducing the disparities gap, progress is contingent upon whether opportunities in the ACA help or hinder populations at risk for impaired health and limited access to medical care. | H11: United States | I11: 73 | J11: FALSE | K11: FALSE | L11: FALSE | M11: n/a abstract | N11: FALSE | Q11: FALSE | R11: =IF(Q11<>N11,"!!!","") | W11: TRUE
A12: SCOPUS_ID:45549105637 | B12: 10.2105/AJPH.2007.121137 | C12: Prevalence of chronic diseases and multimorbidity among the elderly population in Sweden | D12: American Journal of Public Health | E12: 2008 | F12: [] | G12: We explored the role of age, gender, and socioeconomic status in the occurrence of chronic diseases and multimorbidity in 1099 elderly participants in the Kungsholmen Project. Cardiovascular and mental diseases were the most common chronic disorders. Of the participants, 55% had multimorbidity. Advanced age, female gender, and lower education were independently associated with a more than 50% increased risk for multimorbidity. Multimorbidity is the most common clinical picture of the elderly and may be increased by unhealthy behaviors linked to education. | H12: Sweden | I12: 312 | J12: FALSE | K12: FALSE | L12: FALSE | N12: FALSE | Q12: FALSE | R12: =IF(Q12<>N12,"!!!","") | W12: FALSE
A13: SCOPUS_ID:0025121054 | B13: 10.2105/AJPH.80.9.1101 | C13: The effects of workplace health promotion on absenteeism and employment costs in a large industrial population | D13: American Journal of Public Health | E13: 1990 | F13: [] | G13: We evaluated the impact of a comprehensive workplace health promotion program on absences among full-time employees in a large, multi-location, diversified industrial company. A pretest-posttest control group design was used to study 41 intervention sites and 19 control sites with 29,315 and 14,573 hourly employees, respectively. Blue-collar employees at intervention sites experienced an 14.0 percent decline in disability days over two years versus a 5.8 percent decline at control sites. This resulted in a net difference of 11,726 fewer disability days over two years at program sites compared with non-program sites. Savings due to lower disability costs at intervention sites offset program costs in the first year, and provided a return of $2.05 for every dollar invested in the program by the end of the second year. These results suggest that comprehensive workplace health promotion programs can reduce disability days among blue collar employees and provide a good return on investiment. | H13: United States | I13: 161 | J13: FALSE | K13: FALSE | L13: FALSE | N13: FALSE | Q13: FALSE | R13: =IF(Q13<>N13,"!!!","") | W13: FALSE
A14: SCOPUS_ID:84875598366 | B14: 10.1093/ije/dys214 | C14: Consistently high estimates for the proportion of human exposure to malaria vector populations occurring indoors in rural Africa | D14: International Journal of Epidemiology | E14: 2013 | F14: ['Behavior', 'Exposure', 'Malaria', 'Plasmodium', 'Transmission', 'Vector'] | G14: Background Insecticide-treated nets (ITNs) and indoor residual spraying (IRS) are highly effective tools for controlling malaria transmission in Africa because the most important vectors, from the Anopheles gambiae complex and the A. funestus group, usually prefer biting humans indoors at night. Methods Matched surveys of mosquito and human behaviour from six rural sites in Burkina Faso, Tanzania, Zambia, and Kenya, with ITN use ranging from 0.2 to 82.5, were used to calculate the proportion of human exposure to An. gambiae sensu lato and An. funestus s.l. that occurs indoors (Ï€i), as an indicator of the upper limit of personal protection that indoor vector control measures can provide. This quantity was also estimated through use of a simplified binary analysis (Ï€iB) so that the proportions of mosquitoes caught indoors (Pi), and between the first and last hours at which most people are indoors (Pfl) could also be calculated as underlying indicators of feeding by mosquitoes indoors or at night, respectively. Results The vast majority of human exposure to Anopheles bites occurred indoors (iB 0.79-1.00). Neither An. gambiae s.l. nor An. funestus s.l. strongly preferred feeding indoors (Pi 0.40-0.63 and 0.22-0.69, respectively), but they overwhelmingly preferred feeding at times when most humans were indoors (Pfl 0.78-1.00 and 0.86-1.00, respectively). Conclusions These quantitative summaries of behavioural interactions between humans and mosquitoes constitute a remarkably consistent benchmark with which future observations of vector behaviour can be compared. Longitudinal monitoring of these quantities is vital to evaluate the effectiveness of ITNs and IRS and the need for complementary measures that target vectors outdoors. Published by Oxford University Press on behalf of the International Epidemiological Association. Â© The Author 2013; all rights reserved. | H14: Burkina Faso | I14: 129 | J14: FALSE | K14: TRUE | L14: FALSE | M14: marginal - research is called for not policy? | N14: FALSE | O14: Yes research recommendation, not sure how to filter those, maybe iterations of further research needed | P14: I added to the LLM prompt that research recommendations don't count as policy recommendations; they might not be able to distinguish. New prompt=FALSE | Q14: FALSE | R14: =IF(Q14<>N14,"!!!","") | W14: FALSE
A15: SCOPUS_ID:85045210606 | B15: 10.1016/j.amepre.2018.01.008 | C15: Changes in School Food Preparation Methods Result in Healthier Cafeteria Lunches in Elementary Schools | D15: American Journal of Preventive Medicine | E15: 2018 | F15: [] | G15: Introduction: The purpose of this study is to examine the impact of a districtwide food best practices and preparation changes in elementary schools lunches, implemented as part of the LiveWell@School childhood obesity program, funded by LiveWell Colorado/Kaiser Permanente Community Health Initiative. Methods: Longitudinal study examining how school changes in best practices for food preparation impacted the types of side items offered from 2009 to 2015 in elementary school cafeterias in a high-need school district in southern Colorado. Specifically, this study examined changes in side items (fruits, vegetables, potatoes, breads, and desserts). In Phase 1 (2009â€“2010), baseline data were collected. During Phase 2 (2010â€“2011), breaded and processed foods (e.g., frozen nuggets, pre-packaged pizza) were removed and school chefs were trained on scratch cooking methods. Phase 3 (2011â€“2012) saw an increased use of fresh/frozen fruits and vegetables after a new commodity order. During Phase 4 (2013â€“2015), chef consulting and training took place. The frequency of side offerings was tracked across phases. Analyses were completed in Fall 2016. Because of limited sample sizes, data from Phases 2 to 4 (intervention phases) were combined for potatoes and desserts. Descriptive statistics were calculated. After adjusting for length of time for each phase, Pearson chi-square tests were conducted to examine changes in offerings of side items by phase. Results: Fresh fruit offerings increased and canned fruit decreased in Phases 1â€“4 (p=0.001). A significant difference was observed for vegetables (p=0.001), with raw and steamed vegetables increasing and canned vegetables decreasing from Phase 1 to 4. Fresh potatoes (low in sodium) increased and fried potatoes (high in sodium) decreased from Phase 1 to Phases 2â€“4 (p=0.001). Breads were eliminated entirely in Phase 2, and dessert changes were not significant (p=0.927). Conclusions: This approach to promoting healthier lunch sides is a promising paradigm for improving elementary cafeteria food offerings. Supplement information: This article is part of a supplement entitled Building Thriving Communities Through Comprehensive Community Health Initiatives, which is sponsored by Kaiser Permanente, Community Health. | H15: United States | I15: 8 | J15: FALSE | K15: FALSE | L15: FALSE | N15: FALSE | Q15: FALSE | R15: =IF(Q15<>N15,"!!!","") | W15: FALSE
A16: SCOPUS_ID:0031194498 | B16: 10.1006/pmed.1997.0151 | C16: Epidemiology of low total plasma cholesterol concentration among young adults: The CARDIA study | D16: Preventive Medicine | E16: 1997 | F16: ['Cholesterol', 'Risk factors', 'Young adults'] | G16: Background. Data on stability of plasma total cholesterol levels and its determinants among young adults are lacking. Knowledge of factors associated with low levels of plasma total cholesterol during young adulthood may help clarify the nature of associations between hypocholesterolemia and health or illness. Methods. Tracking of plasma total cholesterol was investigated using data from the baseline (1985-1986), Year 5 (1990-1991), and Year 7 (1992- 1993) examinations of the Coronary Artery Risk Development in Young Adults Study. Lifestyle (including dietary), physiological, medical, and psychological correlates of plasma total cholesterol were examined cross- sectionally at baseline using ANCOVA and multivariate logistic regression. The attributes of participants with persistently low plasma total cholesterol level after 7 years (i.e., remaining below the 10th percentile of sex- and race-specific distributions) were also examined. Results. The cohort in this analysis comprised 720 black men, 922 white men, 899 black women, and 944 white women who were between the ages of 18 and 30 years at baseline. Between 44 and 52% of those with plasma total cholesterol levels below the 10th percentile remained below the same percentile 7 years later. Among black men, a difference of 1 SD in age [3.7 years; odds ratio (OR) = 0.69; 95% CI = 0.52-0.91] and a difference of 1 SD in systolic blood pressure (10.5 mm Hg; OR = 0.73; 95% CI = 0.54-0.97) were independently associated with lower odds, respectively, of being in the lowest 10th percentile of the plasma total cholesterol distribution. Also among black men, current smoking and more calories from carbohydrates were associated with nonsignificantly higher odds of low total cholesterol level. Among white men, a 1 SD older age (3.4 years; OR = 0.78; 95% CI = 0.61-1.00) and a 1 SD higher physical fitness (118 see; OR = 1.41; 95% CI = 1.09-1.82) predicted lower and higher odds, respectively, of low plasma total cholesterol. Among black women, a 1 SD difference in albumin (0.3 g/dL; OR = 0.80; 95% CI = 0.63-1.03) was related to lower odds of low plasma total cholesterol. Among white women, the factors independently associated with low plasma total cholesterol were body mass index (OR for a difference in 4.0 kg/m2 = 0.73; 95% CI = 0.54-1.00) and Î³-glutamyl transferase (OR for an increase in 9.6 IU/L = 0.41; 95% CI = 0.18-0.93). The independent predictive factors of stably low total cholesterol levels were age and uric acid among black men (both inversely related) and age, Framingham Type A Behavior (inversely), and calories from carbohydrates (positively related) among white men. Conclusion: Young adults with low plasma total cholesterol level have characteristics generally associated with good cardiovascular health. However, adverse attributes such as current cigarette smoking (notably among black men) may confound future associations between low total cholesterol and disease. | H16: United States | I16: 9 | J16: FALSE | K16: FALSE | L16: FALSE | N16: FALSE | Q16: FALSE | R16: =IF(Q16<>N16,"!!!","") | W16: FALSE
A17: SCOPUS_ID:0029924623 | B17: 10.1097/00001648-199605000-00011 | C17: Silica and aluminum in drinking water and cognitive impairment in the elderly | D17: Epidemiology | E17: 1996 | F17: ['aluminum', "Alzheimer's disease", 'cognitive impairment', 'dementia', 'drinking water', 'elderly', 'silicon'] | G17: We studied the relation between silica and aluminum levels in drinking water and the risk of cognitive impairment using data from a population- based survey of 3,777 French subjects age 65 years and older. We also studied the effect of pH and the concentrations of calcium, magnesium, fluorine, zinc, copper, and iron. We used a mixed effects logistic regression adjusting for age, sex, educational level, and occupation of the subjects. We confirmed the inverse relation previously found between calcium level and cognitive impairment. We found no important association between cognitive impairment and fluorine, magnesium, iron, copper, or zinc. The association between cognitive impairment and aluminum depended on the pH and the concentration of silica: high levels of aluminum appeared to have a deleterious effect when the silica concentration was low, but there was a protective effect when the pH and the silica level were high. The threshold for an aluminum effect, however, was very low (3.5 Î¼g per liter) and did not support the hypothesis of a deleterious effect for only high levels of aluminum. | H17: France | I17: 63 | J17: FALSE | K17: FALSE | L17: FALSE | N17: FALSE | Q17: FALSE | R17: =IF(Q17<>N17,"!!!","") | W17: FALSE
A18: SCOPUS_ID:85102828933 | B18: 10.1016/j.ypmed.2021.106507 | C18: Associations between indicators of energy intake and expenditure with excess weight and obesity among women in sedentary and less-sedentary jobs | D18: Preventive Medicine | E18: 2021 | F18: ['Dietary questionnaire for epidemiological studies', 'Energy balance', 'Obesity', 'Physical activity', 'Saturated fat', 'Sedentary work', 'Sugar sweetened beverages'] | G18: The aim of this study was to compare the associations between indicators of energy intake and expenditure with excess weight and obesity in women who work full-time in sedentary and less sedentary jobs. Data were from 3444 participants the Australian Longitudinal Study on Women's Health, who reported their weight, dietary intake, physical activity and occupation in 2009 (baseline), and weight in 2012 (follow-up). Participants were categorised as being in a â€˜less sedentaryâ€™ or â€˜sedentaryâ€™ job, based on occupational activity patterns. Odds of excess weight (BMI â‰¥ 25) at baseline and of being obese (BMI â‰¥ 30) at follow-up, by indicators of energy intake and expenditure, were compared in the two occupational groups. In multivariate analyses, high non-work sitting time and saturated fat intake were associated with increased odds of obesity at 3-year follow-up in both occupational groups. In the sedentary job group, high physical activity (in leisure and transport) was associated with a 51% reduction in odds of obesity (OR 0.49, 95%CI 0.25â€“0.97). In the less-sedentary job group, energy intake and high soft drink consumption were associated with markedly increased odds of obesity (OR 1.67 95%CI 1.07â€“2.61; OR 2.08 95%CI1.42â€“3.05, respectively). In this cohort of young Australian women, sedentariness at work did not markedly affect the prevalence of excess weight or obesity. Indicators of high energy intake and low energy expenditure were associated with increased odds of both excess weight and obesity, regardless of sedentariness of occupational group. | H18: Australia | I18: 1 | J18: FALSE | K18: FALSE | L18: FALSE | N18: FALSE | Q18: FALSE | R18: =IF(Q18<>N18,"!!!","") | W18: FALSE
A19: SCOPUS_ID:0141997855 | B19: 10.1093/aje/kwg218 | C19: Differences in body shape representations among young adults from a biracial (Black-White), semirural community: The Bogalusa Heart Study | D19: American Journal of Epidemiology | E19: 2003 | F19: ['Blacks', 'Body image', 'Body mass index', 'Body weight', 'Perception', 'Psychology', 'Whites'] | G19: In this study, the authors examined body image perception and body mass index (weight (kg)/height (m)2) among race-gender groups in a biracial (Black-White) population of young adults in Bogalusa, Louisiana. A mail-out survey was completed in 1994 by 3,698 (65%) participants aged 18.5-35 years in the Bogalusa Heart Study (mean age = 27.6 years). As part of the survey, body image perception was determined in terms of body shape representation from a figure rating scale. A body image discrepancy score was calculated from the difference between z-standardized values of body image perception and body mass index. A stepwise proportional odds model including the covariates income, employment, education, and physical activity was used to identify factors influencing lower perception of body shape. Mean body mass index was highest among Black females (p < 0.001). The odds of having a lower perception of body shape (vs. body mass index) were 1.72 times higher in Blacks (p < 0.001), 0.80 times lower in persons who were currently employed (p < 0.001), and 0.86 times lower in persons with a higher education (p = 0.032). Gender, income, and physical activity were not found to be significant predictors of body image perception (p > 0.05). The authors conclude that significant differences exist within racial groups concerning body image perception in relation to overweight status among young adults. This has implications for prevention and education programs. | H19: United States | I19: 84 | J19: FALSE | K19: FALSE | L19: TRUE | M19: "This has implications" - marginal, but still… | N19: TRUE | O19: Hard one, they do say policy implications but without specifying. | P19: LLM prompt edited for generic "this has policy implications" abstracts. New prompt=TRUE | Q19: TRUE | R19: =IF(Q19<>N19,"!!!","") | W19: TRUE
A20: SCOPUS_ID:85195147269 | B20: 10.1007/s10654-024-01134-4 | C20: Trends in incidence and mortality of early-onset cancer in Germany between 1999 and 2019 | D20: European Journal of Epidemiology | E20: 2024 | F20: ['Cancer', 'Germany', 'Incidence', 'Mortality'] | G20: Evidence on the recent temporal trend in the incidence and mortality of early-onset cancer, i.e., cancer diagnosed at ages of < 50 years, in Germany is scarce. To estimate the temporal trend in the incidence and mortality of early-onset cancer in Germany between 1999 and 2019. Input data were obtained from the Centre for Cancer Registry Data (Zentrum fÃ¼r Krebsregisterdaten, ZfKD). The analysis comprised all ages until 50 years and all types of cancer classified by the International Classification of Diseases (ICD-10)-codes C00-C97 (excl. C44). Temporal trends were estimated using negative binomial regression, differentiated by sex and cancer type. Between 1999 and 2019 in Germany, we observed stable or slightly increasing trends (0% and 1%) in the incidence of all early-onset cancers combined (C00-C97) for men and women, respectively, and strict declines in the mortality for both, men and women (-2% and âˆ’ 3%). However, the trends differ largely with respect to sex and the individual cancer types. Early-onset cancer should be closely monitored to see whether stable and decreasing trends in the incidence and mortality continue. Knowing that despite decreasing incidence, the prevalence of a disease can rise due to their interplay with mortality, we recommend to maintain precise surveillance, efforts in prevention and early detection, as well as appropriate investments into healthcare resources, research and development. | H20: Germany | I20: 1 | J20: FALSE | K20: TRUE | L20: TRUE | N20: TRUE | O20: We recommend followed by policy | Q20: TRUE | R20: =IF(Q20<>N20,"!!!","") | W20: TRUE
A21: SCOPUS_ID:0037209068 | B21: 10.1097/00001648-200301000-00009 | C21: The effect of concurvity in generalized additive models linking mortality to ambient particulate matter | D21: Epidemiology | E21: 2003 | F21: ['Air pollution', 'Concurvity', 'Generalized additive model', 'PM 10', 'PM 2.5', 'Sulfate particles'] | G21: In recent years, a number of studies have applied generalized additive models to time series data to estimate associations between exposure to air pollution and cardiorespiratory morbidity and mortality. If concurvity, the nonparametric analogue of multicollinearity, is present in the data, statistical software such as S-plus can seriously underestimate the variance of fitted model parameters, leading to significance tests with inflated type 1 error. This paper uses computer simulation and analyses of actual epidemiologic data to explore this underestimation of standard errors. We provide a method for assessing concurvity in data and an alternate class of models that is unaffected by concurvity. We argue that some degree of concurvity is likely to be present in all epidemiologic time series datasets and we explore through the use of meta-analysis the possible impact of concurvity on the existing body of work relating ambient levels of sulfate particles to mortality. Copyright Â© 2002 by Lippincott Williams & Wilkins, Inc. | H21: Canada | I21: 212 | J21: FALSE | K21: FALSE | L21: FALSE | N21: FALSE | Q21: FALSE | R21: =IF(Q21<>N21,"!!!","") | W21: FALSE
A22: SCOPUS_ID:85097113376 | B22: 10.1093/aje/kwaa139 | C22: Incidence Correction Factors for Moderate and Severe Acute Child Malnutrition from 2 Longitudinal Cohorts in Mali and Burkina Faso | D22: American Journal of Epidemiology | E22: 2020 | F22: ['burden of acute malnutrition', 'child acute malnutrition', 'cumulative incidence', 'incidence correction factor K', 'longitudinal data', 'moderate acute malnutrition', 'prevalence', 'severe acute malnutrition'] | G22: Child acute malnutrition (AM) is an important cause of child mortality. Accurately estimating its burden requires cumulative incidence data from longitudinal studies, which are rarely available in low-income settings. In the absence of such data, the AM burden is approximated using prevalence estimates from cross-sectional surveys and the incidence correction factor $K$, obtained from the few available cohorts that measured AM. We estimated $K$ factors for severe acute malnutrition (SAM) and moderate acute malnutrition (MAM) from AM incidence and prevalence using representative cross-sectional baseline and longitudinal data from 2 cluster-randomized controlled trials (Innovative Approaches for the Prevention of Childhood Malnutrition-PROMIS) conducted between 2014 and 2017 in Burkina Faso and Mali. We compared K estimates using complete (weight-for-length z score, mid-upper arm circumference (MUAC), and edema) and partial (MUAC, edema) definitions of SAM and MAM. $K$ estimates for SAM were 9.4 and 5.7 in Burkina Faso and in Mali, respectively; K estimates for MAM were 4.7 in Burkina Faso and 5.1 in Mali. The MUAC and edema-based definition of AM did not lead to different $K$ estimates. Our results suggest that $K$ can be reliably estimated when only MUAC and edema-based data are available. Additional studies, however, are required to confirm this finding in different settings. | H22: United States | I22: 5 | J22: FALSE | K22: FALSE | L22: FALSE | N22: FALSE | Q22: FALSE | R22: =IF(Q22<>N22,"!!!","") | W22: FALSE
A23: SCOPUS_ID:70249102791 | B23: 10.1093/aje/kwp179 | C23: Determinants of first puff and daily cigarette smoking in adolescents | D23: American Journal of Epidemiology | E23: 2009 | F23: ['Adolescent', 'Epidemiologic factors', 'Incidence', 'Longitudinal studies', 'Risk factors', 'Smoking'] | G23: Few prospective studies of smoking initiation have investigated a wide range of time-varying and invariant predictor variables at the individual and contextual levels concurrently. In this study (1999-2005), 877 Canadian students (mean age=12.7 years) who had never smoked at baseline completed self-report questionnaires on cigarette smoking and 32 predictor variables in 20 survey cycles during secondary school. Height and weight were measured in survey cycles 1, 12, and 19. School administrators completed questionnaires on school tobacco control policies/activities, and trained observers collected data on access to tobacco products in commercial establishments near schools. Younger age, single-parent family status, smoking by parents, siblings, friends, and school staff, stress, impulsivity, lower self-esteem, feeling a need to smoke, not doing well at school, susceptibility to tobacco advertising, alcohol use, use of other tobacco products, and attending a smoking-tolerant school were independent determinants of smoking initiation. Independent determinants of daily smoking onset among initiators of nondaily smoking included smoking by siblings and friends, feeling a need to smoke, susceptibility to tobacco advertising, use of other tobacco products, and self-perceived mental and physical addiction. Adolescent tobacco control programs should address multiple individual and contextual-level risk factors. Strategies that address nicotine dependence symptoms are also needed for adolescents who have already initiated smoking. | H23: Canada | I23: 186 | J23: FALSE | K23: TRUE | L23: TRUE | M23: clear | N23: TRUE | O23: Agreed, with the use of 'strategies' | Q23: TRUE | R23: =IF(Q23<>N23,"!!!","") | W23: TRUE
A24: SCOPUS_ID:0031689886 | B24: 10.1016/S0749-3797(98)00049-X | C24: Costs of maternal conditions attributable to smoking during pregnancy | D24: American Journal of Preventive Medicine | E24: 1998 | F24: ['Cost', 'Economics', 'Health behavior', 'Health care costs', 'Pregnancy', 'Smoking', 'Surveys'] | G24: Context: Despite known adverse health effects, many women continue to smoke during pregnancy. Public attention has now focused on the economic as well as health effects of this behavior. Objective: To estimate health care costs associated with smoking-attributable cases of placenta previa, abruptio placenta, ectopic pregnancy, preterm premature rupture of the membrane (PPROM), pre-eclampsia, and spontaneous abortion. Design: Pooled odds ratios were used with data on total cases to estimate smoking-attributable cases. Estimated average costs for cases of ectopic pregnancy and spontaneous abortion were used to estimate smoking-attributable health care costs for these conditions. Incremental costs, or costs above those for a 'normal' delivery, were used to estimate smoking-attributable costs of placenta previa, abruptio placenta, PPROM, and pre- eclampsia associated with delivery. Setting: National estimates for 1993. Participants: Data from the National Hospital Discharge Survey (NHDS) and claims data from a sample of large, self-insured employers across the country. Results: Smoking- attributable costs ranged from $1.3 million for PPROM to $86 million for ectopic pregnancy. Smoking during pregnancy apparently protects against pre- eclampsia and saves between $36 and $49 million, depending on smoking prevalence. Over all conditions smoking-attributable costs ranged from $135 to $167 million. Conclusions: Smoking during pregnancy is a preventable cause of higher health care costs for the conditions studied. While smoking during pregnancy was found to be protective against pre-eclampsia and, hence, saves costs, the net costs were still positive and significant, Effective smoking- cessation programs can reduce health care costs but clinicians will perhaps need to manage increased cases of pre-eclampsia in a cost-effective manner. | H24: United States | I24: 35 | J24: FALSE | K24: TRUE | L24: TRUE | M24: marginal | N24: TRUE | Q24: TRUE | R24: =IF(Q24<>N24,"!!!","") | W24: TRUE
A25: SCOPUS_ID:85149642428 | B25: 10.2105/AJPH.2022.307207 | C25: Housing Instability and Evictions Linked to Elevated Intimate Partner and Workplace Violence Among Women Sex Workers in Vancouver, Canada: Findings of a Prospective, Community-Based Cohort, 2010-2019 | D25: American Journal of Public Health | E25: 2022 | F25: [] | G25: Objectives. To model the relationship of unstable housing and evictions with physical and sexual violence perpetrated against women sex workers in intimate and workplace settings. Methods. We used bivariate and multivariable logistic regression with generalized estimating equations to model the association of unstable housing exposure and evictions with intimate partner violence (IPV) and workplace violence among a community-based longitudinal cohort of cisgender and transgender women sex workers in Vancouver, Canada, from 2010 through 2019. Results. Of 946 women, 85.9% experienced unstable housing, 11.1% eviction, 26.2% IPV, and 31.8% workplace violence. In multivariable generalized estimating equation models, recent exposure to unstable housing (adjusted odds ratio [AOR]52.04; 95% confidence interval [CI]51.45, 2.87) and evictions (AOR52.45; 95% CI50.99, 6.07) were associated with IPV, and exposure to unstable housing was associated with workplace violence (AOR51.46; 95% CI51.06, 2.00). Conclusions. Women sex workers face a high burden of unstable housing and evictions, which are linked to increased odds of intimate partner and workplace violence. Increased access to safe, womencentered, and nondiscriminatory housing is urgently needed. | H25: United States | I25: 4 | J25: FALSE | K25: TRUE | L25: TRUE | M25: clear | N25: TRUE | Q25: TRUE | R25: =IF(Q25<>N25,"!!!","") | W25: TRUE
A26: SCOPUS_ID:0028286476 | B26: 10.1136/jech.48.3.313 | C26: Estimating confidence limits on a standardised mortality ratio when the expected number is not error free | D26: Journal of Epidemiology & Community Health | E26: 1994 | F26: [] | G26: Objective - The aim was to demonstrate how the beta distribution may be used to find confidence limits on a standardised mortality ratio (SMR) when the expected number of events is subject to random variation and to compare these limits with those obtained with the standard exact approach used for SMRs and with a Fieller-based confidence interval. Design - The relationship of the binomial and the beta distributions is explained. For cohort studies in which deaths are counted in exposed and unexposed groups exact confidence limits on the relative risk are found conditional on the total number of observed deaths. A similar method for the SMR is justified by analogy between the SMR and the relative risk found from such cohort studies, and the fact that the relevant (beta) distribution does not require integer parameters. Source of data - Illustrative examples of hypothetical data were used, together with a MINITAB macro to perform the calculations. Main results - Exact confidence intervals that include error in the expected number are much wider than those found with the standard exact method. Fieller intervals are comparable with the new exact method provided the observed and expected numbers (taken to be means of Poisson variates) are large enough to approximate normality. As the expected number is increased, the standard method gives results closer to the new method, but may still lead to different conclusions even with as many as 100 expected. Conclusions - If there is reason to suppose the expected number of deaths in an SMR is subject to sampling error (because of imprecisely estimated rates in the standard population) then exact confidence limits should be found by the methods described here, or approximate Fieller-based limits provided enough events are observed and expected to approximate normality. | H26: United Kingdom | I26: 40 | J26: FALSE | K26: TRUE | L26: FALSE | M26: clear LLM mistake? | N26: FALSE | O26: Agreed, not sure what it picked up here | P26: me neither - all we can do is a the best with our prompts | Q26: FALSE | R26: =IF(Q26<>N26,"!!!","") | W26: FALSE
A27: SCOPUS_ID:0028784286 | B27: 10.1093/oxfordjournals.aje.a117747 | C27: Preschool physical activity level and change in body fatness in young children: The framingham children's study | D27: American Journal of Epidemiology | E27: 1995 | F27: ['Child', 'Exercise', 'Obesity', 'Prospective studies', 'Skinfold thickness'] | G27: This study examined the effect of preschool physical activity on the change in body fatness from preschool to first grade. The Framingham Children's Study, a longitudinal study of childhood cardiovascular risk behaviors, began in 1987 with the enrollment of 106 children aged 3-5 years and their parents. The present analyses include 97 healthy children with complete data from study entry into first grade. Physical activity was assessed twice yearly for 5 days with an electronic motion sensor. The authors estimated change in the child's level of body fat from preschool to first grade by using the slopes of triceps and subscapular skinfolds and body mass index. On average, active girls (i.e., those with above-median activity levels) gained 1.0 mm in their triceps skinfolds from baseline to first grade, while inactive girls gained 1.75 mm. Active boys lost an average of 0.75 mm in their triceps, while inactive boys gained 0.25 mm. When age, television viewing, energy intake, baseline triceps, and parents' body mass indices were controlled for, inactive preschoolers were 3.8 (95% confidence interval 1.4-10.6) times as likely as active preschoolers to have an increasing triceps slope during follow up (rather than a stable or decreasing slope). This relative risk estimate was slightly higher for children with more body fat at baseline. In this study, preschool-aged children with low levels of physical activity gained substantially more subcutaneous fat than did more active children. Â© 1995 Copyright 1995 by The Johns Hopkins University School of Hygiene and Public Health. | H27: United States | I27: 211 | J27: FALSE | K27: FALSE | L27: FALSE | N27: FALSE | Q27: FALSE | R27: =IF(Q27<>N27,"!!!","") | W27: FALSE
A28: SCOPUS_ID:85123459610 | B28: 10.1093/ije/dyab095 | C28: Maternal smoking and smokeless tobacco use during pregnancy and offspring development: Sibling analysis in an intergenerational Swedish cohort | D28: International Journal of Epidemiology | E28: 2021 | F28: ['confounding', 'fetal growth restriction', 'Intellectual disability', 'maternal prenatal smoking', 'siblings', 'snus'] | G28: Background: The association between maternal smoking in pregnancy and offspring intellectual disability (ID) is less well understood than that of smoking and fetal growth restriction. As fetal growth and cognitive development may share similar confounding structures, comparison of the two associations may improve understanding of the causal nature of the association with ID. Furthermore, comparisons of smoking with smokeless tobacco use may aid identification of mechanisms of action. Methods: This was a cohort study of all Swedish births between 1999 and 2012 (n = 1 070 013), with prospectively recorded data. We assessed the association between maternal smoking during pregnancy and offspring outcomes ID and born small for gestational age (SGA). Analyses were repeated for snus use in pregnancy. Using a sibling design, we estimated within-family effects that control for shared sibling characteristics. Results: Those exposed to maternal smoking in pregnancy had increased odds of ID [odds ratio (OR) = 1.24, 95% confidence interval (CI): 1.16-1.33] and SGA (OR = 2.19, 95% CI: 2.11-2.27) after confounder adjustment. Within-family effects were found for SGA (OR = 1.44, 95% CI: 1.27-1.63) but not ID (OR = 0.92, 95% CI: 0.74-1.14). For snus use, the results for ID were similar to smoking. We found increased odds of offspring SGA among mothers who used snus in pregnancy in sensitivity analyses but not in primary analyses. Conclusions: Our findings are consistent with a causal effect of maternal smoking in pregnancy on risk of offspring born SGA but not on risk of ID. We found no evidence for a causal effect of snus use in pregnancy on ID and inconclusive evidence for SGA. | H28: United Kingdom | I28: 8 | J28: FALSE | K28: FALSE | L28: FALSE | N28: FALSE | Q28: FALSE | R28: =IF(Q28<>N28,"!!!","") | W28: FALSE
A29: SCOPUS_ID:0028997640 | B29: 10.2105/AJPH.85.6.854 | C29: A preventive child health program: The effect of telephone and home visits by public health nurses | D29: American Journal of Public Health | E29: 1995 | F29: [] | G29: A randomized trial was conducted to determine if a public health nursing intervention consisting of telephone contacts or home visits affected the receipt of preventive health services by children eligible for the Early Periodic Screening, Diagnosis, and Treatment program. Each nursing intervention was applied using a protocol, and outcome data for 1654 case subjects were obtained from state-paid provider claims. However, the trial revealed no statistically significant differences between the study groups, nor was ethnicity a significant factor. Methodological and study context issues were identified that may have affected the results, the generalization of which is limited by the strict selection of cases. | H29: United States | I29: 20 | J29: FALSE | K29: FALSE | L29: FALSE | N29: FALSE | Q29: FALSE | R29: =IF(Q29<>N29,"!!!","") | W29: FALSE
A30: SCOPUS_ID:78650909890 | B30: 10.2105/AJPH.2009.182287 | C30: Potential national and state medical care savings from primary disease prevention | D30: American Journal of Public Health | E30: 2011 | F30: [] | G30: Objectives: We estimated national and state-level potential medical care cost savings achievable through modest reductions in the prevalence of several diseases associated with the same lifestyle-related risk factors. Methods: Using Medical Expenditure Panel Survey Household Component data (2003-2005), we estimated the effects on medical spending over time of reductions in the prevalence of diabetes, hypertension, and related conditions amenable to primary prevention by comparing simulated counterfactual morbidity and medical care expenditures to actual disease and expenditure patterns. We produced state-level estimates of spending by using multivariate reweighting techniques. Results. Nationally, we estimated that reducing diabetes and hypertension prevalence by 5% would save approximately $9 billion annually in the near term. With resulting reductions in comorbidities and selected related conditions, savings could rise to approximately $24.7 billion annually in the medium term. Returns were greatest in absolute terms for private payers, but greatest in percentage terms for public payers. State savings varied with demographic makeup and prevailing morbidity. Conclusions. Well-designed interventions that achieve improvements in lifestyle-related risk factors could result in sufficient savings in the short and medium term to substantially offset intervention costs. | H30: United States | I30: 22 | J30: FALSE | K30: TRUE | L30: FALSE | M30: clear LLM mistake? | N30: FALSE | O30: Agreed, not sure what it picked up here | Q30: TRUE | R30: =IF(Q30<>N30,"!!!","") -> !!! | W30: TRUE
A31: SCOPUS_ID:0026733346 | B31: 10.1093/oxfordjournals.aje.a116486 | C31: Childhood weight and growth rate as predictors of adult mortality | D31: American Journal of Epidemiology | E31: 1992 | F31: ['Anthropometry', 'Body height', 'Body weight', 'Child', 'Growth', 'Mortality'] | G31: The effect of rate of growth and relative weight in childhood on adult mortality was studied among 13,146 persons whose weights and heights were measured between the ages of 5 and 18 years in Hagerstown, Maryland, during the period 1933-1945. Relative weight was defined internally, age- and sex-specific Z-scores for height and weight were calculated using national standards, and height and weight velocities were measured as annual increments. Associations between growth parameters (pre- and postpubertal) and mortality through 1985 were investigated in subjects who matched the 1963 and 1975 private health censuses of Washington County, Maryland, using a nested case-control design. Odds ratios of mortality increased linearly with prepubertal relative weight (p < 0.05 for both sexes combined) and with postpubertal relative weight in females (p < 0.01). The associations between growth velocities or attained height with mortality tended to be inverse, although not statistically significant. These results are compatible with the existence of positive associations of overweight in school-age children with long-term mortality and seem to allay fears that harm could come from increased growth rates in childhood. Without jeopardizing growth, the avoidance of overweight in childhood might reduce mortality in middle age. Am J Epidemiol1992;136:201-13. Â© 1992 by The Johns Hopkins University School of Hypiene and Public Health. | H31: United States | I31: 207 | J31: FALSE | K31: TRUE | L31: FALSE | M31: clear LLM mistake? | N31: FALSE | O31: Agreed, not sure what it picked up here | Q31: TRUE | R31: =IF(Q31<>N31,"!!!","") -> !!! | W31: TRUE
